[2024-02-26T15:31:58.108+0000] {taskinstance.py:1956} INFO - Dependencies all met for dep_context=non-requeueable deps ti=<TaskInstance: yearly.pyspark_task manual__2024-02-26T15:16:42.637142+00:00 [queued]>
[2024-02-26T15:31:58.112+0000] {taskinstance.py:1956} INFO - Dependencies all met for dep_context=requeueable deps ti=<TaskInstance: yearly.pyspark_task manual__2024-02-26T15:16:42.637142+00:00 [queued]>
[2024-02-26T15:31:58.113+0000] {taskinstance.py:2170} INFO - Starting attempt 4 of 4
[2024-02-26T15:31:58.119+0000] {taskinstance.py:2191} INFO - Executing <Task(DataprocSubmitJobOperator): pyspark_task> on 2024-02-26 15:16:42.637142+00:00
[2024-02-26T15:31:58.125+0000] {standard_task_runner.py:60} INFO - Started process 8219 to run task
[2024-02-26T15:31:58.129+0000] {standard_task_runner.py:87} INFO - Running: ['***', 'tasks', 'run', 'yearly', 'pyspark_task', 'manual__2024-02-26T15:16:42.637142+00:00', '--job-id', '187', '--raw', '--subdir', 'DAGS_FOLDER/main.py', '--cfg-path', '/tmp/tmpfsfhxxt1']
[2024-02-26T15:31:58.130+0000] {standard_task_runner.py:88} INFO - Job 187: Subtask pyspark_task
[2024-02-26T15:31:58.164+0000] {task_command.py:423} INFO - Running <TaskInstance: yearly.pyspark_task manual__2024-02-26T15:16:42.637142+00:00 [running]> on host 756a22f68d7e
[2024-02-26T15:31:58.213+0000] {taskinstance.py:2480} INFO - Exporting env vars: AIRFLOW_CTX_DAG_EMAIL='nguyentuanduong555@gmail.com' AIRFLOW_CTX_DAG_OWNER='Duong_' AIRFLOW_CTX_DAG_ID='yearly' AIRFLOW_CTX_TASK_ID='pyspark_task' AIRFLOW_CTX_EXECUTION_DATE='2024-02-26T15:16:42.637142+00:00' AIRFLOW_CTX_TRY_NUMBER='4' AIRFLOW_CTX_DAG_RUN_ID='manual__2024-02-26T15:16:42.637142+00:00'
[2024-02-26T15:31:58.215+0000] {dataproc.py:2208} INFO - Submitting job
[2024-02-26T15:31:58.229+0000] {taskinstance.py:2698} ERROR - Task failed with exception
Traceback (most recent call last):
  File "/home/airflow/.local/lib/python3.8/site-packages/airflow/models/taskinstance.py", line 433, in _execute_task
    result = execute_callable(context=context, **execute_callable_kwargs)
  File "/home/airflow/.local/lib/python3.8/site-packages/airflow/providers/google/cloud/operators/dataproc.py", line 2209, in execute
    self.hook = DataprocHook(gcp_conn_id=self.gcp_conn_id, impersonation_chain=self.impersonation_chain)
  File "/home/airflow/.local/lib/python3.8/site-packages/airflow/providers/google/cloud/hooks/dataproc.py", line 210, in __init__
    super().__init__(gcp_conn_id=gcp_conn_id, impersonation_chain=impersonation_chain)
  File "/home/airflow/.local/lib/python3.8/site-packages/airflow/providers/google/common/hooks/base_google.py", line 242, in __init__
    self.extras: dict = self.get_connection(self.gcp_conn_id).extra_dejson
  File "/home/airflow/.local/lib/python3.8/site-packages/airflow/hooks/base.py", line 82, in get_connection
    conn = Connection.get_connection_from_secrets(conn_id)
  File "/home/airflow/.local/lib/python3.8/site-packages/airflow/models/connection.py", line 479, in get_connection_from_secrets
    raise AirflowNotFoundException(f"The conn_id `{conn_id}` isn't defined")
airflow.exceptions.AirflowNotFoundException: The conn_id `google_cloud_default` isn't defined
[2024-02-26T15:31:58.232+0000] {taskinstance.py:1138} INFO - Marking task as FAILED. dag_id=yearly, task_id=pyspark_task, execution_date=20240226T151642, start_date=20240226T153158, end_date=20240226T153158
[2024-02-26T15:31:58.237+0000] {standard_task_runner.py:107} ERROR - Failed to execute job 187 for task pyspark_task (The conn_id `google_cloud_default` isn't defined; 8219)
[2024-02-26T15:31:58.262+0000] {local_task_job_runner.py:234} INFO - Task exited with return code 1
[2024-02-26T15:31:58.305+0000] {taskinstance.py:3280} INFO - 0 downstream tasks scheduled from follow-on schedule check
